#VRML_SIM R2025a utf8

EXTERNPROTO "https://raw.githubusercontent.com/cyberbotics/webots/R2025a/projects/objects/backgrounds/protos/TexturedBackground.proto"
EXTERNPROTO "https://raw.githubusercontent.com/cyberbotics/webots/R2025a/projects/objects/backgrounds/protos/TexturedBackgroundLight.proto"
EXTERNPROTO "https://raw.githubusercontent.com/cyberbotics/webots/R2025a/projects/objects/floors/protos/Floor.proto"

WorldInfo {
  basicTimeStep 16
}
Viewpoint {
  orientation 0.49540345624129395 0.4201667709464364 -0.760286327732273 1.9961393838863222
  position 0.13511497315725485 0.26453967393422134 0.9185046873814242
}
TexturedBackground {
}
TexturedBackgroundLight {
}
Floor {
  size 1 1
}
Solid {
  translation 0 0.5 0.05
  children [
    DEF WALL Shape {
      appearance PBRAppearance {
        baseColor 0.152544 0.175265 1
        roughness 0.5
        metalness 0
      }
      geometry Box {
        size 1 0.04 0.1
      }
    }
  ]
  name "wall"
  boundingObject USE WALL
  physics Physics {
    mass 1
  }
}
Solid {
  translation 0 -0.5 0.05
  rotation 0 0 1 3.14159
  children [
    USE WALL
  ]
  name "wall 2"
  boundingObject USE WALL
  physics Physics {
    mass 1
  }
}
Solid {
  translation 0.5 0 0.05
  rotation 0 0 1 -1.5707953071795862
  children [
    USE WALL
  ]
  name "wall 3"
  boundingObject USE WALL
  physics Physics {
    mass 1
  }
  translationStep 0
}
Solid {
  translation -0.49 -1.00941e-06 0.05
  rotation 0 0 1 -1.5707953071795862
  children [
    USE WALL
  ]
  name "wall 4"
  boundingObject USE WALL
  physics Physics {
    mass 1
  }
}
Robot {
  translation 0 0 0.03
  children [
    DistanceSensor {
      translation 0.11 0.02 0
      rotation 0 0 0.9999999999999999 0.3000000000000006
      children [
        Solid {
          children [
            Shape {
              appearance PBRAppearance {
                baseColor 0.2 0.258824 1
              }
              geometry Box {
                size 0.01 0.01 0.01
              }
            }
          ]
          name "ds_1"
        }
      ]
      name "ds_left"
      numberOfRays 3
    }
    DistanceSensor {
      translation 0.11 -0.02 0
      rotation 0 0 1 -0.3
      children [
        Solid {
          children [
            Shape {
              appearance PBRAppearance {
                baseColor 0.2 0.258824 1
              }
              geometry Box {
                size 0.01 0.01 0.01
              }
            }
          ]
        }
      ]
      name "ds_right"
      numberOfRays 3
    }
    HingeJoint {
      jointParameters HingeJointParameters {
        axis 0 1 0
        anchor 0.05 0.06 0
      }
      device [
        RotationalMotor {
          name "wheel_2"
        }
      ]
      endPoint Solid {
        translation 0.05 0.06 0
        rotation 1 0 0 1.5708
        children [
          DEF Wheel Shape {
            appearance PBRAppearance {
              baseColor 0.0608835 1 0.145205
            }
            geometry Cylinder {
              height 0.02
              radius 0.04
            }
          }
        ]
        name "Wheel_2"
        boundingObject USE Wheel
        physics Physics {
        }
      }
    }
    HingeJoint {
      jointParameters HingeJointParameters {
        axis 0 1 0
        anchor -0.05 -0.06 0
      }
      device [
        RotationalMotor {
          name "wheel_1"
        }
      ]
      endPoint Solid {
        translation -0.05 -0.06 0
        rotation 1 0 0 1.5708
        children [
          DEF Wheel Shape {
            appearance PBRAppearance {
              baseColor 0.0608835 1 0.145205
            }
            geometry Cylinder {
              height 0.02
              radius 0.04
            }
          }
        ]
        name "Wheel_1"
        boundingObject USE Wheel
        physics Physics {
        }
      }
    }
    HingeJoint {
      jointParameters HingeJointParameters {
        axis 0 1 0
        anchor -0.05 0.06 0
      }
      device [
        RotationalMotor {
          name "wheel_3"
        }
      ]
      endPoint Solid {
        translation -0.05 0.06 0
        rotation 1 0 0 1.5708
        children [
          DEF Wheel Shape {
            appearance PBRAppearance {
              baseColor 0.0608835 1 0.145205
            }
            geometry Cylinder {
              height 0.02
              radius 0.04
            }
          }
        ]
        name "Wheel_3"
        boundingObject USE Wheel
        physics Physics {
        }
      }
    }
    DEF robot_body Shape {
      appearance PBRAppearance {
        baseColor 1 0.138323 0.184833
      }
      geometry Box {
        size 0.2 0.1 0.05
      }
    }
    HingeJoint {
      jointParameters HingeJointParameters {
        axis 0 1 0
        anchor 0.05 -0.06 0
      }
      device [
        RotationalMotor {
          name "wheel_4"
        }
      ]
      endPoint Solid {
        translation 0.05 -0.06 0
        rotation 1 0 0 1.5708
        children [
          DEF Wheel Shape {
            appearance PBRAppearance {
              baseColor 0.0608835 1 0.145205
            }
            geometry Cylinder {
              height 0.02
              radius 0.04
            }
          }
        ]
        name "Wheel_4"
        boundingObject USE Wheel
        physics Physics {
        }
      }
    }
  ]
  boundingObject USE robot_body
  physics Physics {
  }
  controller "four_wheeled_collision_avoidance"
}
